Workbook

Sheet MDS
B3: Multidimensional Scaling
B6: Purpose: reduction of multidimensionality (similar to PCA).
B7: Method: This is a nonlinear method (which is a big advantage). The algorithm places points on the plane so that the dependencies are best preserved.
B9: Implementation:
B10: 1) Define the distance between objects (eg Euclidean distance) in the original N-dimensional space
B16: 2) Define the distance between objects (eg Euclidean distance) in a new n-dimensional space
B21: 3) Define the STRESS function - its value depends on the distance relationship in both spaces. For similar distance distributions the function takes its minimum
B22: The most popular is the Kruskal scaling:
H24: Where Dij is the distance in the original space N
H25: dij is the distance in the new space n
B28: 4) Minimize the objective function in iterations

Sheet MDS example
O3: Step 2 | P3: Preparation of distance matrix in N-dimensional space
Q5: It is about counting the distance in pairs for the next variables (that is, for each pair of observations of a pair of variables)
Q6: Distance is the sum of the squared differences - you can use the function: SUMA.XMY.2 ()
B7: How to perform multivariate scaling? | Q7: We fill the matrix by rows - in the first row 1: 1, 1: 2, 1: 3, 1: 4 etc
Q8: In the second line: 2: 1, 2: 2, 2: 3 etc
B9: Step 1 Data capture | Q9: That means that we always have one locked column and one variable in the row
B10: Let's say we want to draw 100 respondents on a subjective evaluation of 10 products. | N10: how many rows | O10: =ROWS(C16:L115) -> 100 | Q10: To smoothly fill in the matrix by rows (in fact change the blocked column), use the SHIFT() (PRZESUNIĘCIE) function.
B11: Ratings range from 1 (best) to 10 (worst). | N11: how many columns | O11: {=ROWS(TRANSPOSE(C16:L115))} -> 10 | Q11: You can prepare a surface empirical plot to see which pair of distances are the lowest.
B12: Here below we have random numbers drawen from different distributions
O13: Matrix of empirical distance Dij
B14: pattern | C14: =ROUND(RAND()*2+3,0) -> 5 | D14: =ROUND(RAND()*2+3,0) -> 5 | E14: =ROUND(RAND()*2+3,0) -> 4 | F14: =ROUND(RAND()*2+3,0) -> 3 | G14: =ROUND(RAND()*3,0) -> 3 | H14: =ROUND(RAND()*3,0) -> 1 | I14: =ROUND(RAND()*3,0) -> 1 | J14: =ROUND(RAND()*4+5,0) -> 5 | K14: =ROUND(RAND()*4+5,0) -> 5 | L14: =ROUND(RAND()*4+5,0) -> 9 | Q14: 1 | R14: 2 | S14: 3 | T14: 4 | U14: 5 | V14: 6 | W14: 7 | X14: 8 | Y14: 9 | Z14: 10
B15: Customer | C15: Rating of product 1 | D15: Rating of product 2 | E15: Rating of product 3 | F15: Rating of product 4 | G15: Rating of product 5 | H15: Rating of product 6 | I15: Rating of product 7 | J15: Rating of product 8 | K15: Rating of product 9 | L15: Rating of product 10 | Q15: Rating of product 1 | R15: Rating of product 2 | S15: Rating of product 3 | T15: Rating of product 4 | U15: Rating of product 5 | V15: Rating of product 6 | W15: Rating of product 7 | X15: Rating of product 8 | Y15: Rating of product 9 | Z15: Rating of product 10
B16: 1 | C16: 3 | D16: 3 | E16: 5 | F16: 3 | G16: 2 | H16: 3 | I16: 1 | J16: 6 | K16: 6 | L16: 7 | O16: 1 | P16: Rating of product 1 | Q16: =SUMXMY2(OFFSET($C$16,0,$O16-1,$O$10),OFFSET($C$16,0,Q$14-1,$O$10))^0.5 -> 0 | R16: =SUMXMY2(OFFSET($C$16,0,$O16-1,$O$10),OFFSET($C$16,0,R$14-1,$O$10))^0.5 -> 10.440307 | S16: =SUMXMY2(OFFSET($C$16,0,$O16-1,$O$10),OFFSET($C$16,0,S$14-1,$O$10))^0.5 -> 9.1104336 | T16: =SUMXMY2(OFFSET($C$16,0,$O16-1,$O$10),OFFSET($C$16,0,T$14-1,$O$10))^0.5 -> 9.2736185 | U16: =SUMXMY2(OFFSET($C$16,0,$O16-1,$O$10),OFFSET($C$16,0,U$14-1,$O$10))^0.5 -> 28.354894 | V16: =SUMXMY2(OFFSET($C$16,0,$O16-1,$O$10),OFFSET($C$16,0,V$14-1,$O$10))^0.5 -> 27.313001 | W16: =SUMXMY2(OFFSET($C$16,0,$O16-1,$O$10),OFFSET($C$16,0,W$14-1,$O$10))^0.5 -> 28.390139 | X16: =SUMXMY2(OFFSET($C$16,0,$O16-1,$O$10),OFFSET($C$16,0,X$14-1,$O$10))^0.5 -> 32.572995 | ... Z16: =SUMXMY2(OFFSET($C$16,0,$O16-1,$O$10),OFFSET($C$16,0,Z$14-1,$O$10))^0.5 -> 34.842503
B17: 2 | C17: 3 | D17: 5 | E17: 4 | F17: 5 | G17: 1 | H17: 1 | I17: 3 | J17: 6 | K17: 6 | L17: 7 | O17: 2 | P17: Rating of product 2 | Q17: =SUMXMY2(OFFSET($C$16,0,$O17-1,$O$10),OFFSET($C$16,0,Q$14-1,$O$10))^0.5 -> 10.440307 | R17: =SUMXMY2(OFFSET($C$16,0,$O17-1,$O$10),OFFSET($C$16,0,R$14-1,$O$10))^0.5 -> 0 | S17: =SUMXMY2(OFFSET($C$16,0,$O17-1,$O$10),OFFSET($C$16,0,S$14-1,$O$10))^0.5 -> 10.583005 | T17: =SUMXMY2(OFFSET($C$16,0,$O17-1,$O$10),OFFSET($C$16,0,T$14-1,$O$10))^0.5 -> 9.9498744 | U17: =SUMXMY2(OFFSET($C$16,0,$O17-1,$O$10),OFFSET($C$16,0,U$14-1,$O$10))^0.5 -> 27.440845 | V17: =SUMXMY2(OFFSET($C$16,0,$O17-1,$O$10),OFFSET($C$16,0,V$14-1,$O$10))^0.5 -> 26.627054 | W17: =SUMXMY2(OFFSET($C$16,0,$O17-1,$O$10),OFFSET($C$16,0,W$14-1,$O$10))^0.5 -> 27.404379 | X17: =SUMXMY2(OFFSET($C$16,0,$O17-1,$O$10),OFFSET($C$16,0,X$14-1,$O$10))^0.5 -> 34.146742 | ... Z17: =SUMXMY2(OFFSET($C$16,0,$O17-1,$O$10),OFFSET($C$16,0,Z$14-1,$O$10))^0.5 -> 35.566838
B18: 3 | C18: 5 | D18: 3 | E18: 3 | F18: 4 | G18: 0 | H18: 0 | I18: 1 | J18: 5 | K18: 9 | L18: 5 | O18: 3 | P18: Rating of product 3 | Q18: =SUMXMY2(OFFSET($C$16,0,$O18-1,$O$10),OFFSET($C$16,0,Q$14-1,$O$10))^0.5 -> 9.1104336 | R18: =SUMXMY2(OFFSET($C$16,0,$O18-1,$O$10),OFFSET($C$16,0,R$14-1,$O$10))^0.5 -> 10.583005 | S18: =SUMXMY2(OFFSET($C$16,0,$O18-1,$O$10),OFFSET($C$16,0,S$14-1,$O$10))^0.5 -> 0 | T18: =SUMXMY2(OFFSET($C$16,0,$O18-1,$O$10),OFFSET($C$16,0,T$14-1,$O$10))^0.5 -> 10.148892 | U18: =SUMXMY2(OFFSET($C$16,0,$O18-1,$O$10),OFFSET($C$16,0,U$14-1,$O$10))^0.5 -> 27.073973 | V18: =SUMXMY2(OFFSET($C$16,0,$O18-1,$O$10),OFFSET($C$16,0,V$14-1,$O$10))^0.5 -> 25.980762 | W18: =SUMXMY2(OFFSET($C$16,0,$O18-1,$O$10),OFFSET($C$16,0,W$14-1,$O$10))^0.5 -> 27.037012 | X18: =SUMXMY2(OFFSET($C$16,0,$O18-1,$O$10),OFFSET($C$16,0,X$14-1,$O$10))^0.5 -> 33.105891 | ... Z18: =SUMXMY2(OFFSET($C$16,0,$O18-1,$O$10),OFFSET($C$16,0,Z$14-1,$O$10))^0.5 -> 34.94281
B19: 4 | C19: 5 | D19: 5 | E19: 4 | F19: 4 | G19: 0 | H19: 0 | I19: 0 | J19: 6 | K19: 8 | L19: 7 | O19: 4 | P19: Rating of product 4 | Q19: =SUMXMY2(OFFSET($C$16,0,$O19-1,$O$10),OFFSET($C$16,0,Q$14-1,$O$10))^0.5 -> 9.2736185 | R19: =SUMXMY2(OFFSET($C$16,0,$O19-1,$O$10),OFFSET($C$16,0,R$14-1,$O$10))^0.5 -> 9.9498744 | S19: =SUMXMY2(OFFSET($C$16,0,$O19-1,$O$10),OFFSET($C$16,0,S$14-1,$O$10))^0.5 -> 10.148892 | T19: =SUMXMY2(OFFSET($C$16,0,$O19-1,$O$10),OFFSET($C$16,0,T$14-1,$O$10))^0.5 -> 0 | U19: =SUMXMY2(OFFSET($C$16,0,$O19-1,$O$10),OFFSET($C$16,0,U$14-1,$O$10))^0.5 -> 27.055499 | V19: =SUMXMY2(OFFSET($C$16,0,$O19-1,$O$10),OFFSET($C$16,0,V$14-1,$O$10))^0.5 -> 26.34388 | W19: =SUMXMY2(OFFSET($C$16,0,$O19-1,$O$10),OFFSET($C$16,0,W$14-1,$O$10))^0.5 -> 26.570661 | X19: =SUMXMY2(OFFSET($C$16,0,$O19-1,$O$10),OFFSET($C$16,0,X$14-1,$O$10))^0.5 -> 33.54102 | ... Z19: =SUMXMY2(OFFSET($C$16,0,$O19-1,$O$10),OFFSET($C$16,0,Z$14-1,$O$10))^0.5 -> 35.185224
B20: 5 | C20: 4 | D20: 5 | E20: 5 | F20: 3 | G20: 1 | H20: 1 | I20: 2 | J20: 8 | K20: 8 | L20: 5 | O20: 5 | P20: Rating of product 5 | Q20: =SUMXMY2(OFFSET($C$16,0,$O20-1,$O$10),OFFSET($C$16,0,Q$14-1,$O$10))^0.5 -> 28.354894 | R20: =SUMXMY2(OFFSET($C$16,0,$O20-1,$O$10),OFFSET($C$16,0,R$14-1,$O$10))^0.5 -> 27.440845 | S20: =SUMXMY2(OFFSET($C$16,0,$O20-1,$O$10),OFFSET($C$16,0,S$14-1,$O$10))^0.5 -> 27.073973 | T20: =SUMXMY2(OFFSET($C$16,0,$O20-1,$O$10),OFFSET($C$16,0,T$14-1,$O$10))^0.5 -> 27.055499 | U20: =SUMXMY2(OFFSET($C$16,0,$O20-1,$O$10),OFFSET($C$16,0,U$14-1,$O$10))^0.5 -> 0 | V20: =SUMXMY2(OFFSET($C$16,0,$O20-1,$O$10),OFFSET($C$16,0,V$14-1,$O$10))^0.5 -> 13.416408 | W20: =SUMXMY2(OFFSET($C$16,0,$O20-1,$O$10),OFFSET($C$16,0,W$14-1,$O$10))^0.5 -> 14.21267 | X20: =SUMXMY2(OFFSET($C$16,0,$O20-1,$O$10),OFFSET($C$16,0,X$14-1,$O$10))^0.5 -> 57.297469 | ... Z20: =SUMXMY2(OFFSET($C$16,0,$O20-1,$O$10),OFFSET($C$16,0,Z$14-1,$O$10))^0.5 -> 58.600341
B21: 6 | C21: 5 | D21: 3 | E21: 4 | F21: 5 | G21: 2 | H21: 3 | I21: 2 | J21: 8 | K21: 8 | L21: 8 | O21: 6 | P21: Rating of product 6 | Q21: =SUMXMY2(OFFSET($C$16,0,$O21-1,$O$10),OFFSET($C$16,0,Q$14-1,$O$10))^0.5 -> 27.313001 | R21: =SUMXMY2(OFFSET($C$16,0,$O21-1,$O$10),OFFSET($C$16,0,R$14-1,$O$10))^0.5 -> 26.627054 | S21: =SUMXMY2(OFFSET($C$16,0,$O21-1,$O$10),OFFSET($C$16,0,S$14-1,$O$10))^0.5 -> 25.980762 | T21: =SUMXMY2(OFFSET($C$16,0,$O21-1,$O$10),OFFSET($C$16,0,T$14-1,$O$10))^0.5 -> 26.34388 | U21: =SUMXMY2(OFFSET($C$16,0,$O21-1,$O$10),OFFSET($C$16,0,U$14-1,$O$10))^0.5 -> 13.416408 | V21: =SUMXMY2(OFFSET($C$16,0,$O21-1,$O$10),OFFSET($C$16,0,V$14-1,$O$10))^0.5 -> 0 | W21: =SUMXMY2(OFFSET($C$16,0,$O21-1,$O$10),OFFSET($C$16,0,W$14-1,$O$10))^0.5 -> 12 | X21: =SUMXMY2(OFFSET($C$16,0,$O21-1,$O$10),OFFSET($C$16,0,X$14-1,$O$10))^0.5 -> 55.973208 | ... Z21: =SUMXMY2(OFFSET($C$16,0,$O21-1,$O$10),OFFSET($C$16,0,Z$14-1,$O$10))^0.5 -> 57.480431
B22: 7 | C22: 3 | D22: 4 | E22: 4 | F22: 4 | G22: 1 | H22: 1 | I22: 1 | J22: 6 | K22: 5 | L22: 8 | O22: 7 | P22: Rating of product 7 | Q22: =SUMXMY2(OFFSET($C$16,0,$O22-1,$O$10),OFFSET($C$16,0,Q$14-1,$O$10))^0.5 -> 28.390139 | R22: =SUMXMY2(OFFSET($C$16,0,$O22-1,$O$10),OFFSET($C$16,0,R$14-1,$O$10))^0.5 -> 27.404379 | S22: =SUMXMY2(OFFSET($C$16,0,$O22-1,$O$10),OFFSET($C$16,0,S$14-1,$O$10))^0.5 -> 27.037012 | T22: =SUMXMY2(OFFSET($C$16,0,$O22-1,$O$10),OFFSET($C$16,0,T$14-1,$O$10))^0.5 -> 26.570661 | U22: =SUMXMY2(OFFSET($C$16,0,$O22-1,$O$10),OFFSET($C$16,0,U$14-1,$O$10))^0.5 -> 14.21267 | V22: =SUMXMY2(OFFSET($C$16,0,$O22-1,$O$10),OFFSET($C$16,0,V$14-1,$O$10))^0.5 -> 12 | W22: =SUMXMY2(OFFSET($C$16,0,$O22-1,$O$10),OFFSET($C$16,0,W$14-1,$O$10))^0.5 -> 0 | X22: =SUMXMY2(OFFSET($C$16,0,$O22-1,$O$10),OFFSET($C$16,0,X$14-1,$O$10))^0.5 -> 57.070132 | ... Z22: =SUMXMY2(OFFSET($C$16,0,$O22-1,$O$10),OFFSET($C$16,0,Z$14-1,$O$10))^0.5 -> 58.634461
B23: 8 | C23: 4 | D23: 4 | E23: 4 | F23: 3 | G23: 3 | H23: 1 | I23: 2 | J23: 7 | K23: 9 | L23: 7 | O23: 8 | P23: Rating of product 8 | Q23: =SUMXMY2(OFFSET($C$16,0,$O23-1,$O$10),OFFSET($C$16,0,Q$14-1,$O$10))^0.5 -> 32.572995 | R23: =SUMXMY2(OFFSET($C$16,0,$O23-1,$O$10),OFFSET($C$16,0,R$14-1,$O$10))^0.5 -> 34.146742 | S23: =SUMXMY2(OFFSET($C$16,0,$O23-1,$O$10),OFFSET($C$16,0,S$14-1,$O$10))^0.5 -> 33.105891 | T23: =SUMXMY2(OFFSET($C$16,0,$O23-1,$O$10),OFFSET($C$16,0,T$14-1,$O$10))^0.5 -> 33.54102 | U23: =SUMXMY2(OFFSET($C$16,0,$O23-1,$O$10),OFFSET($C$16,0,U$14-1,$O$10))^0.5 -> 57.297469 | V23: =SUMXMY2(OFFSET($C$16,0,$O23-1,$O$10),OFFSET($C$16,0,V$14-1,$O$10))^0.5 -> 55.973208 | W23: =SUMXMY2(OFFSET($C$16,0,$O23-1,$O$10),OFFSET($C$16,0,W$14-1,$O$10))^0.5 -> 57.070132 | X23: =SUMXMY2(OFFSET($C$16,0,$O23-1,$O$10),OFFSET($C$16,0,X$14-1,$O$10))^0.5 -> 0 | ... Z23: =SUMXMY2(OFFSET($C$16,0,$O23-1,$O$10),OFFSET($C$16,0,Z$14-1,$O$10))^0.5 -> 19
B24: 9 | C24: 3 | D24: 4 | E24: 3 | F24: 5 | G24: 0 | H24: 1 | I24: 2 | J24: 8 | K24: 7 | L24: 5 | O24: 9 | P24: Rating of product 9 | Q24: =SUMXMY2(OFFSET($C$16,0,$O24-1,$O$10),OFFSET($C$16,0,Q$14-1,$O$10))^0.5 -> 32.726136 | R24: =SUMXMY2(OFFSET($C$16,0,$O24-1,$O$10),OFFSET($C$16,0,R$14-1,$O$10))^0.5 -> 34.322005 | S24: =SUMXMY2(OFFSET($C$16,0,$O24-1,$O$10),OFFSET($C$16,0,S$14-1,$O$10))^0.5 -> 33.941125 | T24: =SUMXMY2(OFFSET($C$16,0,$O24-1,$O$10),OFFSET($C$16,0,T$14-1,$O$10))^0.5 -> 33.600595 | U24: =SUMXMY2(OFFSET($C$16,0,$O24-1,$O$10),OFFSET($C$16,0,U$14-1,$O$10))^0.5 -> 57.489129 | V24: =SUMXMY2(OFFSET($C$16,0,$O24-1,$O$10),OFFSET($C$16,0,V$14-1,$O$10))^0.5 -> 56.753854 | W24: =SUMXMY2(OFFSET($C$16,0,$O24-1,$O$10),OFFSET($C$16,0,W$14-1,$O$10))^0.5 -> 57.766772 | X24: =SUMXMY2(OFFSET($C$16,0,$O24-1,$O$10),OFFSET($C$16,0,X$14-1,$O$10))^0.5 -> 17.262677 | ... Z24: =SUMXMY2(OFFSET($C$16,0,$O24-1,$O$10),OFFSET($C$16,0,Z$14-1,$O$10))^0.5 -> 20.124612
B25: 10 | C25: 5 | D25: 4 | E25: 5 | F25: 3 | G25: 1 | H25: 2 | I25: 3 | J25: 8 | K25: 7 | L25: 8 | O25: 10 | P25: Rating of product 10 | Q25: =SUMXMY2(OFFSET($C$16,0,$O25-1,$O$10),OFFSET($C$16,0,Q$14-1,$O$10))^0.5 -> 34.842503 | R25: =SUMXMY2(OFFSET($C$16,0,$O25-1,$O$10),OFFSET($C$16,0,R$14-1,$O$10))^0.5 -> 35.566838 | S25: =SUMXMY2(OFFSET($C$16,0,$O25-1,$O$10),OFFSET($C$16,0,S$14-1,$O$10))^0.5 -> 34.94281 | T25: =SUMXMY2(OFFSET($C$16,0,$O25-1,$O$10),OFFSET($C$16,0,T$14-1,$O$10))^0.5 -> 35.185224 | U25: =SUMXMY2(OFFSET($C$16,0,$O25-1,$O$10),OFFSET($C$16,0,U$14-1,$O$10))^0.5 -> 58.600341 | V25: =SUMXMY2(OFFSET($C$16,0,$O25-1,$O$10),OFFSET($C$16,0,V$14-1,$O$10))^0.5 -> 57.480431 | W25: =SUMXMY2(OFFSET($C$16,0,$O25-1,$O$10),OFFSET($C$16,0,W$14-1,$O$10))^0.5 -> 58.634461 | X25: =SUMXMY2(OFFSET($C$16,0,$O25-1,$O$10),OFFSET($C$16,0,X$14-1,$O$10))^0.5 -> 19 | ... Z25: =SUMXMY2(OFFSET($C$16,0,$O25-1,$O$10),OFFSET($C$16,0,Z$14-1,$O$10))^0.5 -> 0
B26: 11 | C26: 5 | D26: 5 | E26: 5 | F26: 5 | G26: 1 | H26: 2 | I26: 3 | J26: 8 | K26: 6 | L26: 8
B27: 12 | C27: 3 | D27: 3 | E27: 4 | F27: 4 | G27: 1 | H27: 2 | I27: 1 | J27: 7 | K27: 8 | L27: 9
B28: 13 | C28: 5 | D28: 4 | E28: 4 | F28: 5 | G28: 1 | H28: 1 | I28: 3 | J28: 7 | K28: 8 | L28: 8 | O28: Stage 3 | P28: Prepare the coordinates of a new space
B29: 14 | C29: 3 | D29: 4 | E29: 3 | F29: 3 | G29: 1 | H29: 2 | I29: 1 | J29: 6 | K29: 5 | L29: 8 | P29: The initial values of x and y are (arbitrary) assumed and then optimized
B30: 15 | C30: 4 | D30: 4 | E30: 4 | F30: 4 | G30: 1 | H30: 3 | I30: 2 | J30: 8 | K30: 8 | L30: 7
B31: 16 | C31: 3 | D31: 3 | E31: 4 | F31: 4 | G31: 3 | H31: 1 | I31: 0 | J31: 6 | K31: 6 | L31: 7 | Q31: X | R31: Y
B32: 17 | C32: 4 | D32: 3 | E32: 4 | F32: 5 | G32: 2 | H32: 1 | I32: 3 | J32: 7 | K32: 7 | L32: 7 | P32: Rating of product 1 | Q32: 2.8742367 | R32: 28.569806
B33: 18 | C33: 3 | D33: 4 | E33: 3 | F33: 4 | G33: 1 | H33: 1 | I33: 1 | J33: 8 | K33: 8 | L33: 8 | P33: Rating of product 2 | Q33: 6.2022402 | R33: 25.937321
B34: 19 | C34: 5 | D34: 3 | E34: 4 | F34: 4 | G34: 0 | H34: 1 | I34: 0 | J34: 7 | K34: 8 | L34: 5 | P34: Rating of product 3 | Q34: 15.64671 | R34: 26.819954
B35: 20 | C35: 4 | D35: 3 | E35: 3 | F35: 4 | G35: 2 | H35: 2 | I35: 2 | J35: 6 | K35: 5 | L35: 8 | P35: Rating of product 4 | Q35: 10.899502 | R35: 27.110412
B36: 21 | C36: 5 | D36: 5 | E36: 4 | F36: 3 | G36: 0 | H36: 1 | I36: 0 | J36: 8 | K36: 5 | L36: 7 | P36: Rating of product 5 | Q36: 1.3498634 | R36: 1.795721
B37: 22 | C37: 4 | D37: 3 | E37: 4 | F37: 3 | G37: 1 | H37: 3 | I37: 0 | J37: 8 | K37: 9 | L37: 5 | P37: Rating of product 6 | Q37: 10.555103 | R37: 1.8032396
B38: 23 | C38: 4 | D38: 5 | E38: 5 | F38: 4 | G38: 1 | H38: 3 | I38: 3 | J38: 7 | K38: 8 | L38: 6 | P38: Rating of product 7 | Q38: 18.270279 | R38: 1.9160219
B39: 24 | C39: 3 | D39: 4 | E39: 4 | F39: 3 | G39: 0 | H39: 3 | I39: 2 | J39: 9 | K39: 6 | L39: 8 | P39: Rating of product 8 | Q39: 0 | R39: 58.10375
B40: 25 | C40: 5 | D40: 4 | E40: 4 | F40: 4 | G40: 0 | H40: 1 | I40: 2 | J40: 7 | K40: 8 | L40: 5 | P40: Rating of product 9 | Q40: 10.626119 | R40: 59.920057
B41: 26 | C41: 4 | D41: 3 | E41: 4 | F41: 4 | G41: 1 | H41: 2 | I41: 2 | J41: 9 | K41: 6 | L41: 9 | P41: Rating of product 10 | Q41: 24.191326 | R41: 58.207482
B42: 27 | C42: 4 | D42: 4 | E42: 4 | F42: 4 | G42: 2 | H42: 1 | I42: 2 | J42: 8 | K42: 6 | L42: 8
B43: 28 | C43: 5 | D43: 3 | E43: 4 | F43: 4 | G43: 1 | H43: 2 | I43: 1 | J43: 9 | K43: 7 | L43: 9
...

Sheet PCA
B2: PCA
B3: - linear transformation technique to detect the correlation between variables
B4: - core: to find the directions of maximum variance in high-dimensional data and project it onto a smaller dimensional subspace while retaining most of the information
B5: - purpose: to increase the computational efficiency while retaining most of the information
B6: - main question: How to reduce the dimensions of a d-dimensional dataset by projecting it onto a (k)-dimensional subspace (where k<d)?
B7: - second question: what is the size of k that represents the data ‘well’?
B8: - result: PCA yields the directions (principal components) that maximize the variance of the data, PCA “ignores” class labels
B9: - result: Each of those eigenvectors is associated with an eigenvalue which can be interpreted as the “length” or “magnitude” of the corresponding eigenvector.
B10: - procedure - step 1: calculating the eigenvectors for covariance matrix of standardised data,
B11: - procedure - step 2: checking the degree of explained variance by cumulative eigenvalues and then selecting proper number of eigenvectors
B12: - procedure - step 3: preparing the projection matrix as a result of multiplying the data and selected eigenvectors (principal components).
A21: Step1 | B21: data
U22: Step 2 | V22: Standardised variables | AO22: Step 3 | AP22: covariance matrix | BV22: Step 5 | BW22: Dimensions reductions
A23: mean | B23: =AVERAGE(B26:B405) -> 0.042105263 | C23: =AVERAGE(C26:C405) -> 17 | D23: =AVERAGE(D26:D405) -> 57.80151 | E23: =AVERAGE(E26:E405) -> 29686.329 | F23: =AVERAGE(F26:F405) -> 6236.1368 | G23: =AVERAGE(G26:G405) -> 7998.3263 | H23: =AVERAGE(H26:H405) -> 15451.866 | I23: =AVERAGE(I26:I405) -> 12.268684 | ... R23: =AVERAGE(R26:R405) -> 738.11053 | BG23: Step 4 | BH23: Eigenvectors and eigenvalues
A24: sd | B24: =STDEVA(B26:B405) -> 0.20109408 | C24: =STDEVA(C26:C405) -> 9.4083554 | D24: =STDEVA(D26:D405) -> 32.316128 | E24: =STDEVA(E26:E405) -> 53362.162 | F24: =STDEVA(F26:F405) -> 5447.4473 | G24: =STDEVA(G26:G405) -> 9401.8485 | H24: =STDEVA(H26:H405) -> 45413.819 | I24: =STDEVA(I26:I405) -> 5.2676734 | ... R24: =STDEVA(R26:R405) -> 1826.8902 | AO24: The Excel version | BX24: y - output of PCA
A25: ID_MAPA | B25: core city | C25: region_id | D25: odległość | E25: XA02 | F25: XA03 | G25: XA04 | H25: XA05 | I25: XA06 | J25: XA17 | K25: XA19 | L25: XA20 | M25: XA21 | N25: XA28 | O25: XA30 | P25: XA31 | Q25: XA40 | R25: XA41 | U25: ID_MAPA | V25: core city | W25: region_id | X25: odległość | Y25: XA02 | Z25: XA03 | AA25: XA04 | AB25: XA05 | AC25: XA06 | AD25: XA17 | AE25: XA19 | AF25: XA20 | AG25: XA21 | AH25: XA28 | AI25: XA30 | AJ25: XA31 | AK25: XA40 | AL25: XA41 | AP25: odległość | AQ25: XA02 | AR25: XA03 | AS25: XA04 | AT25: XA05 | AU25: XA06 | AV25: XA17 | AW25: XA19 | AX25: XA20 | AY25: XA21 | AZ25: XA28 | BA25: XA30 | BB25: XA31 | BC25: XA40 | BD25: XA41 | BG25: $values | BV25: Y=X*W | BX25: X - data matrix
A26: 1 | B26: 0 | C26: 18 | D26: 53.835673 | E26: 15582 | F26: 8253 | G26: 3029 | H26: 4300 | I26: 19.8 | J26: 36 | K26: 11715 | L26: 44044 | M26: 11419 | N26: 4145 | O26: 3017.94 | P26: 72.7 | Q26: 403 | R26: 7 | U26: 1 | V26: 0 | W26: 18 | X26: =(D26-D$23)/D$24 -> -0.12272004 | Y26: =(E26-E$23)/E$24 -> -0.2643133 | Z26: =(F26-F$23)/F$24 -> 0.37024005 | AA26: =(G26-G$23)/G$24 -> -0.5285478 | AB26: =(H26-H$23)/H$24 -> -0.24556106 | AC26: =(I26-I$23)/I$24 -> 1.4297234 | AD26: =(J26-J$23)/J$24 -> -0.30792521 | AE26: =(K26-K$23)/K$24 -> -0.33057176 | ... AL26: =(R26-R$23)/R$24 -> -0.40019402 | AO26: odległość | AP26: =VARP(PCA!$X$26:$X$405) -> 0.99736842 | BG26: [1] 9.008684e+00 1.883370e+00 1.199963e+00 9.123390e-01 8.615535e-01 6.641781e-01 1.952730e-01 1.355759e-01 | BX26: W - selected eigenvectors matrix
A27: 2 | B27: 0 | C27: 18 | D27: 55.249937 | E27: 20434 | F27: 14393 | G27: 1123 | H27: 4918 | I27: 17.9 | J27: 125.2 | K27: 14238 | L27: 47878 | M27: 12199 | N27: 4124 | O27: 3195.46 | P27: 77 | Q27: 0 | R27: 1741 | U27: 2 | V27: 0 | W27: 18 | X27: =(D27-D$23)/D$24 -> -0.078956637 | Y27: =(E27-E$23)/E$24 -> -0.17338744 | Z27: =(F27-F$23)/F$24 -> 1.4973735 | AA27: =(G27-G$23)/G$24 -> -0.73127389 | AB27: =(H27-H$23)/H$24 -> -0.23195287 | AC27: =(I27-I$23)/I$24 -> 1.0690328 | AD27: =(J27-J$23)/J$24 -> -0.23991889 | AE27: =(K27-K$23)/K$24 -> -0.20121662 | ... AL27: =(R27-R$23)/R$24 -> 0.54895991 | AO27: XA02 | AP27: -0.14931069 | AQ27: =VARP(PCA!$Y$26:$Y$405) -> 0.99736842 | BG27: [9] 7.402956e-02 4.057037e-02 1.841834e-02 5.014969e-03 1.027390e-03 2.842711e-06 4.778308e-16
A28: 3 | B28: 0 | C28: 18 | D28: 41.176512 | E28: 24367 | F28: 13814 | G28: 4408 | H28: 6145 | I28: 16.9 | J28: 113.3 | K28: 15022 | L28: 49557 | M28: 14290 | N28: 4608 | O28: 3130.09 | P28: 75.4 | Q28: 1687 | R28: 176 | U28: 3 | V28: 0 | W28: 18 | X28: =(D28-D$23)/D$24 -> -0.51444895 | Y28: =(E28-E$23)/E$24 -> -0.099683535 | Z28: =(F28-F$23)/F$24 -> 1.3910852 | AA28: =(G28-G$23)/G$24 -> -0.38187451 | AB28: =(H28-H$23)/H$24 -> -0.20493466 | AC28: =(I28-I$23)/I$24 -> 0.87919569 | AD28: =(J28-J$23)/J$24 -> -0.24899148 | AE28: =(K28-K$23)/K$24 -> -0.16102066 | ... AL28: =(R28-R$23)/R$24 -> -0.30768709 | AO28: XA03 | AP28: 0.025230277 | AQ28: 0.0075680303 | AR28: =VARP(PCA!$Z$26:$Z$405) -> 0.99736842 | BV28: core city | BW28: ID | BX28: prin_comp1 | BY28: all obs | BZ28: core-cities
A29: 4 | B29: 0 | C29: 18 | D29: 26.234316 | E29: 19901 | F29: 8230 | G29: 5539 | H29: 6132 | I29: 17 | J29: 323.1 | K29: 15116 | L29: 46260 | M29: 12380 | N29: 4998 | O29: 3365.62 | P29: 81.1 | Q29: 0 | R29: 0 | U29: 4 | V29: 0 | W29: 18 | X29: =(D29-D$23)/D$24 -> -0.97682475 | Y29: =(E29-E$23)/E$24 -> -0.1833758 | Z29: =(F29-F$23)/F$24 -> 0.36601789 | AA29: =(G29-G$23)/G$24 -> -0.26157902 | AB29: =(H29-H$23)/H$24 -> -0.20522092 | AC29: =(I29-I$23)/I$24 -> 0.8981794 | AD29: =(J29-J$23)/J$24 -> -0.089039403 | AE29: =(K29-K$23)/K$24 -> -0.15620124 | ... AL29: =(R29-R$23)/R$24 -> -0.40402567 | AO29: XA04 | AP29: -0.24620532 | AQ29: 0.88000166 | AR29: -0.13081133 | AS29: =VARP(PCA!$AA$26:$AA$405) -> 0.99736842 | BV29: 0 | BW29: 1 | BX29: {=MMULT($X$26:$AL$405,$BF$89:$BG$103)} -> 1.4990742 | BY29: -1.5193543 | BZ29: =IF(BV29=1,BY29,NA()) -> #N/A
A30: 5 | B30: 0 | C30: 18 | D30: 3.8461907 | E30: 51290 | F30: 26078 | G30: 11030 | H30: 14182 | I30: 12.8 | J30: 589.6 | K30: 33572 | L30: 105406 | M30: 28364 | N30: 11675 | O30: 3333.91 | P30: 80.3 | Q30: 896 | R30: 233 | U30: 5 | V30: 0 | W30: 18 | X30: =(D30-D$23)/D$24 -> -1.6696097 | Y30: =(E30-E$23)/E$24 -> 0.40484999 | Z30: =(F30-F$23)/F$24 -> 3.6424149 | AA30: =(G30-G$23)/G$24 -> 0.32245507 | AB30: =(H30-H$23)/H$24 -> -0.027962101 | AC30: =(I30-I$23)/I$24 -> 0.10086346 | AD30: =(J30-J$23)/J$24 -> 0.11414091 | AE30: =(K30-K$23)/K$24 -> 0.79004464 | ... AL30: =(R30-R$23)/R$24 -> -0.27648653 | AO30: XA05 | AP30: -0.12749857 | AQ30: 0.98883704 | AR30: -0.083661696 | AS30: 0.8432295 | AT30: =VARP(PCA!$AB$26:$AB$405) -> 0.99736842 | BG30: $vectors | BV30: 0 | BW30: 2 | BX30: 1.3091336 | BY30: -1.3875894 | BZ30: =IF(BV30=1,BY30,NA()) -> #N/A
A31: 6 | B31: 0 | C31: 18 | D31: 65.561366 | E31: 31569 | F31: 10781 | G31: 10534 | H31: 10254 | I31: 9.9 | J31: 208 | K31: 17380 | L31: 60541 | M31: 17724 | N31: 6972 | O31: 3251.52 | P31: 78.3 | Q31: 9061 | R31: 0 | U31: 6 | V31: 0 | W31: 18 | X31: =(D31-D$23)/D$24 -> 0.24012333 | Y31: =(E31-E$23)/E$24 -> 0.035281011 | Z31: =(F31-F$23)/F$24 -> 0.83431063 | AA31: =(G31-G$23)/G$24 -> 0.26969948 | AB31: =(H31-H$23)/H$24 -> -0.1144556 | AC31: =(I31-I$23)/I$24 -> -0.44966421 | AD31: =(J31-J$23)/J$24 -> -0.17679195 | AE31: =(K31-K$23)/K$24 -> -0.040125133 | ... AL31: =(R31-R$23)/R$24 -> -0.40402567 | AO31: XA06 | AP31: 0.20698687 | AQ31: -0.29178594 | AR31: 0.01815027 | AS31: -0.45234492 | AT31: -0.25138434 | AU31: =VARP(PCA!$AC$26:$AC$405) -> 0.99736842 | BG31: [,1] [,2] [,3] [,4] [,5] [,6] [,7] [,8] | BV31: 0 | BW31: 3 | BX31: 1.095602 | BY31: -1.46744 | BZ31: =IF(BV31=1,BY31,NA()) -> #N/A
A32: 7 | B32: 0 | C32: 18 | D32: 62.730515 | E32: 33790 | F32: 7183 | G32: 14222 | H32: 12385 | I32: 9.6 | J32: 731.9 | K32: 18093 | L32: 68523 | M32: 21330 | N32: 8926 | O32: 3651.26 | P32: 88 | Q32: 17628 | R32: 164 | U32: 7 | V32: 0 | W32: 18 | X32: =(D32-D$23)/D$24 -> 0.15252464 | Y32: =(E32-E$23)/E$24 -> 0.076902263 | Z32: =(F32-F$23)/F$24 -> 0.17381777 | AA32: =(G32-G$23)/G$24 -> 0.66196277 | AB32: =(H32-H$23)/H$24 -> -0.067531554 | AC32: =(I32-I$23)/I$24 -> -0.50661535 | AD32: =(J32-J$23)/J$24 -> 0.22263081 | AE32: =(K32-K$23)/K$24 -> -0.003569362 | ... AL32: =(R32-R$23)/R$24 -> -0.31425563 | AO32: XA17 | AP32: -0.087396931 | AQ32: 0.94296103 | AR32: -0.076258864 | AS32: 0.80527939 | AT32: 0.95043186 | AU32: -0.25216387 | AV32: =VARP(PCA!$AD$26:$AD$405) -> 0.99736842 | BG32: [1,] 0.070802444 -0.18723939 0.4462621205 0.515271299 0.668335718 0.169331389 -0.1329621858 0.0447718124 | BV32: 0 | BW32: 4 | BX32: 0.84235679 | BY32: -0.47458344 | BZ32: =IF(BV32=1,BY32,NA()) -> #N/A
A33: 8 | B33: 0 | C33: 18 | D33: 27.385669 | E33: 18416 | F33: 11960 | G33: 2134 | H33: 4322 | I33: 20.2 | J33: 23.4 | K33: 11563 | L33: 39208 | M33: 11081 | N33: 3878 | O33: 2990.08 | P33: 72 | Q33: 143 | R33: 20 | U33: 8 | V33: 0 | W33: 18 | X33: =(D33-D$23)/D$24 -> -0.94119693 | Y33: =(E33-E$23)/E$24 -> -0.2112045 | Z33: =(F33-F$23)/F$24 -> 1.0507423 | AA33: =(G33-G$23)/G$24 -> -0.62374185 | AB33: =(H33-H$23)/H$24 -> -0.24507663 | AC33: =(I33-I$23)/I$24 -> 1.5056582 | AD33: =(J33-J$23)/J$24 -> -0.31753148 | AE33: =(K33-K$23)/K$24 -> -0.33836485 | ... AL33: =(R33-R$23)/R$24 -> -0.3930781 | AO33: XA19 | AP33: -0.18283135 | AQ33: 0.95564903 | AR33: 0.076411554 | AS33: 0.88780288 | AT33: 0.92994298 | AU33: -0.30045272 | AV33: 0.88855449 | AW33: =VARP(PCA!$AE$26:$AE$405) -> 0.99736842 | BG33: [2,] -0.325320425 -0.13417357 0.0008312344 0.008209226 0.019957106 -0.015622535 0.1255955038 -0.0424101849 | BV33: 0 | BW33: 5 | BX33: -0.52351265 | BY33: -1.8051625 | BZ33: =IF(BV33=1,BY33,NA()) -> #N/A
A34: 9 | B34: 0 | C34: 18 | D34: 54.263359 | E34: 17778 | F34: 8040 | G34: 5588 | H34: 4150 | I34: 11.1 | J34: 309.4 | K34: 9427 | L34: 34381 | M34: 9903 | N34: 3381 | O34: 3531.2 | P34: 85.1 | Q34: 4487 | R34: 850 | U34: 9 | V34: 0 | W34: 18 | X34: =(D34-D$23)/D$24 -> -0.1094856 | Y34: =(E34-E$23)/E$24 -> -0.22316054 | Z34: =(F34-F$23)/F$24 -> 0.33113917 | AA34: =(G34-G$23)/G$24 -> -0.25636728 | AB34: =(H34-H$23)/H$24 -> -0.24886402 | AC34: =(I34-I$23)/I$24 -> -0.22185965 | AD34: =(J34-J$23)/J$24 -> -0.099484319 | AE34: =(K34-K$23)/K$24 -> -0.44787836 | ... AL34: =(R34-R$23)/R$24 -> 0.061245867 | AO34: XA20 | AP34: -0.19609437 | AQ34: 0.96710957 | AR34: 0.02426466 | AS34: 0.90439004 | AT34: 0.94623046 | AU34: -0.29354107 | AV34: 0.89303404 | AW34: 0.98887734 | AX34: =VARP(PCA!$AF$26:$AF$405) -> 0.99736842 | BG34: [3,] 0.032751824 -0.36520585 -0.4161944821 -0.416937752 0.578447422 -0.344718109 0.0245821342 0.1554504198 | BV34: 0 | BW34: 6 | BX34: 0.36715491 | BY34: -0.8195263 | BZ34: =IF(BV34=1,BY34,NA()) -> #N/A
A35: 10 | B35: 0 | C35: 18 | D35: 85.896728 | E35: 7569 | F35: 4166 | G35: 472 | H35: 2931 | I35: 20.9 | J35: 27.1 | K35: 4684 | L35: 17028 | M35: 5035 | N35: 2933 | O35: 3504.61 | P35: 84.4 | Q35: 934 | R35: 93 | U35: 10 | V35: 0 | W35: 18 | X35: =(D35-D$23)/D$24 -> 0.86938691 | Y35: =(E35-E$23)/E$24 -> -0.41447588 | Z35: =(F35-F$23)/F$24 -> -0.38001962 | AA35: =(G35-G$23)/G$24 -> -0.8005156 | AB35: =(H35-H$23)/H$24 -> -0.27570607 | AC35: =(I35-I$23)/I$24 -> 1.6385442 | AD35: =(J35-J$23)/J$24 -> -0.31471059 | AE35: =(K35-K$23)/K$24 -> -0.6910537 | ... AL35: =(R35-R$23)/R$24 -> -0.35311949 | AO35: XA21 | AP35: -0.17944283 | AQ35: 0.97355692 | AR35: -0.025510287 | AS35: 0.89380851 | AT35: 0.96196745 | AU35: -0.27894475 | AV35: 0.90263188 | AW35: 0.96510328 | AX35: 0.98705648 | AY35: =VARP(PCA!$AG$26:$AG$405) -> 0.99736842 | BG35: [4,] -0.308359346 0.04211311 -0.0898659655 0.007670076 -0.037753206 0.144280609 -0.6432128641 -0.2589123301 | BV35: 0 | BW35: 7 | BX35: -0.41027255 | BY35: 0.29765285 | BZ35: =IF(BV35=1,BY35,NA()) -> #N/A
A36: 11 | B36: 0 | C36: 18 | D36: 43.722853 | E36: 23530 | F36: 480 | G36: 10088 | H36: 12962 | I36: 5.9 | J36: 139.1 | K36: 7823 | L36: 28679 | M36: 10273 | N36: 5639 | O36: 3266.12 | P36: 78.7 | Q36: 18011 | R36: 0 | U36: 11 | V36: 0 | W36: 18 | X36: =(D36-D$23)/D$24 -> -0.4356542 | Y36: =(E36-E$23)/E$24 -> -0.11536881 | Z36: =(F36-F$23)/F$24 -> -1.0566668 | AA36: =(G36-G$23)/G$24 -> 0.222262 | AB36: =(H36-H$23)/H$24 -> -0.05482617 | AC36: =(I36-I$23)/I$24 -> -1.2090127 | AD36: =(J36-J$23)/J$24 -> -0.22932149 | AE36: =(K36-K$23)/K$24 -> -0.53011602 | ... AL36: =(R36-R$23)/R$24 -> -0.40402567 | AO36: XA28 | AP36: -0.12762288 | AQ36: 0.98431667 | AR36: -0.069448091 | AS36: 0.85133123 | AT36: 0.98867468 | AU36: -0.26278818 | AV36: 0.9502138 | AW36: 0.95319854 | AX36: 0.96200833 | AY36: 0.96862756 | AZ36: =VARP(PCA!$AH$26:$AH$405) -> 0.99736842 | BG36: [5,] -0.322348296 -0.12256827 0.0695043976 0.058070332 -0.038119621 -0.006877267 0.2777905016 -0.0148776881 | BV36: 0 | BW36: 8 | BX36: 1.5424432 | BY36: -1.698655 | BZ36: =IF(BV36=1,BY36,NA()) -> #N/A
A37: 12 | B37: 1 | C37: 18 | D37: 0 | E37: 86665 | F37: 3399 | G37: 21268 | H37: 61998 | I37: 7.3 | J37: 1086.5 | K37: 32900 | L37: 117746 | M37: 35250 | N37: 25648 | O37: 4231.81 | P37: 101.9 | Q37: 28763 | R37: 0 | U37: 12 | V37: 1 | W37: 18 | X37: =(D37-D$23)/D$24 -> -1.7886273 | Y37: =(E37-E$23)/E$24 -> 1.0677729 | Z37: =(F37-F$23)/F$24 -> -0.52081951 | AA37: =(G37-G$23)/G$24 -> 1.4113899 | AB37: =(H37-H$23)/H$24 -> 1.0249333 | AC37: =(I37-I$23)/I$24 -> -0.94324074 | AD37: =(J37-J$23)/J$24 -> 0.4929788 | AE37: =(K37-K$23)/K$24 -> 0.75559095 | ... AL37: =(R37-R$23)/R$24 -> -0.40402567 | AO37: XA30 | AP37: -0.1850523 | AQ37: 0.39139964 | AR37: -0.28569362 | AS37: 0.49283884 | AT37: 0.39214133 | AU37: -0.37471198 | AV37: 0.42875015 | AW37: 0.36911312 | AX37: 0.39454029 | AY37: 0.40389363 | AZ37: 0.38951458 | BA37: =VARP(PCA!$AI$26:$AI$405) -> 0.99736842 | BG37: [6,] 0.125542943 -0.29655225 0.4351509034 0.083645277 -0.294026192 -0.753413232 -0.1806515426 -0.0061074135 | BV37: 0 | BW37: 9 | BX37: 0.83813375 | BY37: 0.22650697 | BZ37: =IF(BV37=1,BY37,NA()) -> #N/A
A38: 13 | B38: 0 | C38: 18 | D38: 64.670839 | E38: 18401 | F38: 1399 | G38: 3619 | H38: 13383 | I38: 14.9 | J38: 31.9 | K38: 10165 | L38: 38777 | M38: 13778 | N38: 6262 | O38: 3501.18 | P38: 84.3 | Q38: 13113 | R38: 0 | U38: 13 | V38: 0 | W38: 18 | X38: =(D38-D$23)/D$24 -> 0.21256661 | Y38: =(E38-E$23)/E$24 -> -0.2114856 | Z38: =(F38-F$23)/F$24 -> -0.88796396 | AA38: =(G38-G$23)/G$24 -> -0.46579418 | AB38: =(H38-H$23)/H$24 -> -0.045555864 | AC38: =(I38-I$23)/I$24 -> 0.49952143 | AD38: =(J38-J$23)/J$24 -> -0.31105106 | AE38: =(K38-K$23)/K$24 -> -0.41004083 | ... AL38: =(R38-R$23)/R$24 -> -0.40402567 | AO38: XA31 | AP38: -0.18497237 | AQ38: 0.3915704 | AR38: -0.28575055 | AS38: 0.49299427 | AT38: 0.39231664 | AU38: -0.37472164 | AV38: 0.42891776 | AW38: 0.3692971 | AX38: 0.39472421 | AY38: 0.40406645 | AZ38: 0.38969613 | BA38: 0.99736554 | BB38: =VARP(PCA!$AJ$26:$AJ$405) -> 0.99736842 | BG38: [7,] -0.311410125 -0.08822512 0.0739291001 0.094581459 0.031084447 -0.054147109 0.5213962963 -0.3488711882 | BV38: 0 | BW38: 10 | BX38: 1.6873663 | BY38: -0.24084505 | BZ38: =IF(BV38=1,BY38,NA()) -> #N/A
A39: 14 | B39: 0 | C39: 18 | D39: 60.960978 | E39: 12035 | F39: 1798 | G39: 2352 | H39: 7885 | I39: 13.3 | J39: 50.8 | K39: 7605 | L39: 29868 | M39: 10343 | N39: 4912 | O39: 3284.02 | P39: 79.1 | Q39: 19264 | R39: 0 | U39: 14 | V39: 0 | W39: 18 | X39: =(D39-D$23)/D$24 -> 0.09776753 | Y39: =(E39-E$23)/E$24 -> -0.33078362 | Z39: =(F39-F$23)/F$24 -> -0.81471864 | AA39: =(G39-G$23)/G$24 -> -0.60055492 | AB39: =(H39-H$23)/H$24 -> -0.16662034 | AC39: =(I39-I$23)/I$24 -> 0.19578203 | AD39: =(J39-J$23)/J$24 -> -0.29664165 | AE39: =(K39-K$23)/K$24 -> -0.54129296 | ... AL39: =(R39-R$23)/R$24 -> -0.40402567 | AO39: XA40 | AP39: -0.18905873 | AQ39: 0.89035706 | AR39: -0.21953623 | AS39: 0.83344537 | AT39: 0.89997634 | AU39: -0.30102766 | AV39: 0.83797875 | AW39: 0.84865135 | AX39: 0.87877083 | AY39: 0.89250483 | AZ39: 0.8951921 | BA39: 0.47158394 | BB39: 0.4718028 | BC39: =VARP(PCA!$AK$26:$AK$405) -> 0.99736842 | BG39: [8,] -0.318713574 -0.14589517 -0.0848033577 -0.013518199 0.036821442 -0.055045492 -0.2173853961 -0.0878832145 | BV39: 0 | BW39: 11 | BX39: 0.55700663 | BY39: 0.44102228 | BZ39: =IF(BV39=1,BY39,NA()) -> #N/A
A40: 15 | B40: 0 | C40: 14 | D40: 123.12297 | E40: 15694 | F40: 8236 | G40: 2470 | H40: 4988 | I40: 13.8 | J40: 65 | K40: 10766 | L40: 33010 | M40: 9477 | N40: 3611 | O40: 3485.56 | P40: 84 | Q40: 8722 | R40: 513 | U40: 15 | V40: 0 | W40: 14 | X40: =(D40-D$23)/D$24 -> 2.021327 | Y40: =(E40-E$23)/E$24 -> -0.26221443 | Z40: =(F40-F$23)/F$24 -> 0.36711932 | AA40: =(G40-G$23)/G$24 -> -0.58800419 | AB40: =(H40-H$23)/H$24 -> -0.23041149 | AC40: =(I40-I$23)/I$24 -> 0.29070059 | AD40: =(J40-J$23)/J$24 -> -0.28581553 | AE40: =(K40-K$23)/K$24 -> -0.37922734 | ... AL40: =(R40-R$23)/R$24 -> -0.12322061 | AO40: XA41 | AP40: -0.083587772 | AQ40: -0.027142446 | AR40: 0.0003727294 | AS40: 0.041294244 | AT40: -0.040486625 | AU40: -0.15724018 | AV40: -0.0107969 | AW40: 0.023090636 | AX40: -0.010752193 | AY40: -0.048535065 | AZ40: -0.013433613 | BA40: 0.012047117 | BB40: 0.012012259 | BC40: -0.073933704 | BD40: =VARP(PCA!$AL$26:$AL$405) -> 0.99736842 | BG40: [9,] -0.323811704 -0.12583510 -0.0433336753 -0.025261866 -0.002171374 -0.039718657 -0.2417151758 -0.0280285802 | BV40: 1 | BW40: 12 | BX40: -2.9696663 | BY40: 1.7412802 | BZ40: =IF(BV40=1,BY40,NA()) -> 1.7412802
A41: 16 | B41: 0 | C41: 14 | D41: 35.032622 | E41: 17266 | F41: 3731 | G41: 3930 | H41: 9605 | I41: 13.9 | J41: 410.2 | K41: 14250 | L41: 46644 | M41: 15244 | N41: 8432 | O41: 4003.47 | P41: 96.4 | Q41: 7913 | R41: 2274 | U41: 16 | V41: 0 | W41: 14 | X41: =(D41-D$23)/D$24 -> -0.70456732 | Y41: =(E41-E$23)/E$24 -> -0.23275535 | Z41: =(F41-F$23)/F$24 -> -0.45987354 | AA41: =(G41-G$23)/G$24 -> -0.43271558 | AB41: =(H41-H$23)/H$24 -> -0.1287464 | AC41: =(I41-I$23)/I$24 -> 0.30968431 | AD41: =(J41-J$23)/J$24 -> -0.02263413 | AE41: =(K41-K$23)/K$24 -> -0.20060138 | ... AL41: =(R41-R$23)/R$24 -> 0.84071253 | BG41: [10,] -0.324678204 -0.11737013 0.0124766682 -0.020089306 -0.023718924 -0.016836523 -0.1479173860 -0.0087754878 | BV41: 0 | BW41: 13 | BX41: 0.81804953 | BY41: 0.21631379 | BZ41: =IF(BV41=1,BY41,NA()) -> #N/A
A42: 17 | B42: 0 | C42: 14 | D42: 106.92424 | E42: 16647 | F42: 629 | G42: 5676 | H42: 10342 | I42: 13.3 | J42: 426.6 | K42: 9629 | L42: 33322 | M42: 9620 | N42: 5960 | O42: 4108.75 | P42: 99 | Q42: 32287 | R42: 0 | U42: 17 | V42: 0 | W42: 14 | X42: =(D42-D$23)/D$24 -> 1.5200685 | Y42: =(E42-E$23)/E$24 -> -0.24435533 | Z42: =(F42-F$23)/F$24 -> -1.0293146 | AA42: =(G42-G$23)/G$24 -> -0.24700742 | AB42: =(H42-H$23)/H$24 -> -0.11251786 | AC42: =(I42-I$23)/I$24 -> 0.19578203 | AD42: =(J42-J$23)/J$24 -> -0.010130726 | AE42: =(K42-K$23)/K$24 -> -0.43752174 | ... AL42: =(R42-R$23)/R$24 -> -0.40402567 | BG42: [11,] -0.323922187 -0.12636488 0.0427127682 0.071464633 -0.026658728 -0.012929563 0.2070473755 -0.0464316955 | BV42: 0 | BW42: 14 | BX42: 1.1457277 | BY42: -0.10774421 | BZ42: =IF(BV42=1,BY42,NA()) -> #N/A
A43: 18 | B43: 0 | C43: 14 | D43: 88.700186 | E43: 10129 | F43: 6560 | G43: 1084 | H43: 2485 | I43: 10.9 | J43: 12.4 | K43: 6902 | L43: 20939 | M43: 5728 | N43: 2737 | O43: 3501.61 | P43: 84.4 | Q43: 3400 | R43: 100 | U43: 18 | V43: 0 | W43: 14 | X43: =(D43-D$23)/D$24 -> 0.95613796 | Y43: =(E43-E$23)/E$24 -> -0.36650181 | Z43: =(F43-F$23)/F$24 -> 0.05945228 | AA43: =(G43-G$23)/G$24 -> -0.73542201 | AB43: =(H43-H$23)/H$24 -> -0.28552687 | AC43: =(I43-I$23)/I$24 -> -0.25982708 | AD43: =(J43-J$23)/J$24 -> -0.32591791 | AE43: =(K43-K$23)/K$24 -> -0.57733603 | ... AL43: =(R43-R$23)/R$24 -> -0.34928784 | BG43: [12,] -0.179784139 0.55827565 0.1178852881 -0.079511578 0.229668350 -0.284628694 0.0003836538 0.0007095851 | BV43: 0 | BW43: 15 | BX43: 1.2114294 | BY43: -0.46138224 | BZ43: =IF(BV43=1,BY43,NA()) -> #N/A
A44: 19 | B44: 0 | C44: 14 | D44: 29.047302 | E44: 11698 | F44: 4748 | G44: 2216 | H44: 4734 | I44: 18.7 | J44: 44.9 | K44: 7907 | L44: 28732 | M44: 9353 | N44: 3423 | O44: 3270.47 | P44: 78.8 | Q44: 3798 | R44: 0 | U44: 19 | V44: 0 | W44: 14 | X44: =(D44-D$23)/D$24 -> -0.88977887 | Y44: =(E44-E$23)/E$24 -> -0.33709895 | Z44: =(F44-F$23)/F$24 -> -0.27318059 | AA44: =(G44-G$23)/G$24 -> -0.61502016 | AB44: =(H44-H$23)/H$24 -> -0.2360045 | AC44: =(I44-I$23)/I$24 -> 1.2209025 | AD44: =(J44-J$23)/J$24 -> -0.30113983 | AE44: =(K44-K$23)/K$24 -> -0.52580931 | ... AL44: =(R44-R$23)/R$24 -> -0.40402567 | BG44: [13,] -0.179840925 0.55820108 0.1179666639 -0.079429644 0.229656736 -0.284542789 0.0002630365 0.0010307256 | BV44: 0 | BW44: 16 | BX44: 0.20114009 | BY44: 1.4811506 | BZ44: =IF(BV44=1,BY44,NA()) -> #N/A
A45: 20 | B45: 0 | C45: 14 | D45: 25.383759 | E45: 12504 | F45: 8543 | G45: 1104 | H45: 2857 | I45: 10.1 | J45: 21 | K45: 5831 | L45: 19378 | M45: 6566 | N45: 2308 | O45: 3373.06 | P45: 81.3 | Q45: 1245 | R45: 346 | U45: 20 | V45: 0 | W45: 14 | X45: =(D45-D$23)/D$24 -> -1.0031447 | Y45: =(E45-E$23)/E$24 -> -0.32199462 | Z45: =(F45-F$23)/F$24 -> 0.423476 | AA45: =(G45-G$23)/G$24 -> -0.73329477 | AB45: =(H45-H$23)/H$24 -> -0.27733553 | AC45: =(I45-I$23)/I$24 -> -0.41169678 | AD45: =(J45-J$23)/J$24 -> -0.31936125 | AE45: =(K45-K$23)/K$24 -> -0.63224659 | ... AL45: =(R45-R$23)/R$24 -> -0.21463278 | BG45: [14,] -0.308064107 0.00327799 0.1095057579 0.021131959 -0.130886934 0.088934537 0.0087516782 0.8746829306 | BV45: 0 | BW45: 17 | BX45: 0.24982489 | BY45: 1.5209062 | BZ45: =IF(BV45=1,BY45,NA()) -> #N/A
A46: 21 | B46: 0 | C46: 14 | D46: 88.875256 | E46: 13237 | F46: 6586 | G46: 2189 | H46: 4462 | I46: 20.1 | J46: 30.3 | K46: 10068 | L46: 32316 | M46: 9253 | N46: 3971 | O46: 3165.95 | P46: 76.3 | Q46: 1988 | R46: 8 | U46: 21 | V46: 0 | W46: 14 | X46: =(D46-D$23)/D$24 -> 0.96155538 | Y46: =(E46-E$23)/E$24 -> -0.30825829 | Z46: =(F46-F$23)/F$24 -> 0.064225157 | AA46: =(G46-G$23)/G$24 -> -0.61789193 | AB46: =(H46-H$23)/H$24 -> -0.24199387 | AC46: =(I46-I$23)/I$24 -> 1.4866745 | AD46: =(J46-J$23)/J$24 -> -0.3122709 | AE46: =(K46-K$23)/K$24 -> -0.41501405 | ... AL46: =(R46-R$23)/R$24 -> -0.39964664 | AO46: Paste special: transposition & skip empty cells | BG46: [15,] 0.002697357 0.10442969 -0.6074939980 0.722363090 -0.052693848 -0.293051154 0.0074500027 0.0849288762 | BV46: 0 | BW46: 18 | BX46: 1.3650127 | BY46: 0.11562041 | BZ46: =IF(BV46=1,BY46,NA()) -> #N/A
A47: 22 | B47: 0 | C47: 14 | D47: 63.88595 | E47: 11567 | F47: 7480 | G47: 1102 | H47: 2985 | I47: 19.7 | J47: 25.3 | K47: 7483 | L47: 24610 | M47: 7643 | N47: 2663 | O47: 3181.04 | P47: 76.6 | Q47: 2480 | R47: 110 | U47: 22 | V47: 0 | W47: 14 | X47: =(D47-D$23)/D$24 -> 0.18827874 | Y47: =(E47-E$23)/E$24 -> -0.33955388 | Z47: =(F47-F$23)/F$24 -> 0.22833872 | AA47: =(G47-G$23)/G$24 -> -0.7335075 | AB47: =(H47-H$23)/H$24 -> -0.27451701 | AC47: =(I47-I$23)/I$24 -> 1.4107397 | AD47: =(J47-J$23)/J$24 -> -0.31608292 | AE47: =(K47-K$23)/K$24 -> -0.54754795 | ... AL47: =(R47-R$23)/R$24 -> -0.34381406 | BG47: [,9] [,10] [,11] [,12] [,13] [,14] [,15] | BV47: 0 | BW47: 19 | BX47: 1.4008256 | BY47: -0.43422468 | BZ47: =IF(BV47=1,BY47,NA()) -> #N/A
A48: 23 | B48: 0 | C48: 14 | D48: 21.144336 | E48: 24363 | F48: 14203 | G48: 4702 | H48: 5458 | I48: 8.7 | J48: 191.2 | K48: 16365 | L48: 50385 | M48: 14653 | N48: 5393 | O48: 3253.13 | P48: 78.4 | Q48: 0 | R48: 205 | U48: 23 | V48: 0 | W48: 14 | X48: =(D48-D$23)/D$24 -> -1.1343306 | Y48: =(E48-E$23)/E$24 -> -0.099758494 | Z48: =(F48-F$23)/F$24 -> 1.4624948 | AA48: =(G48-G$23)/G$24 -> -0.35060407 | AB48: =(H48-H$23)/H$24 -> -0.22006222 | AC48: =(I48-I$23)/I$24 -> -0.67746876 | AD48: =(J48-J$23)/J$24 -> -0.18960031 | AE48: =(K48-K$23)/K$24 -> -0.092164555 | ... AL48: =(R48-R$23)/R$24 -> -0.29181312 | AP48: odległość | AQ48: XA02 | AR48: XA03 | AS48: XA04 | AT48: XA05 | AU48: XA06 | AV48: XA17 | AW48: XA19 | AX48: XA20 | AY48: XA21 | AZ48: XA28 | BA48: XA30 | BB48: XA31 | BC48: XA40 | BD48: XA41 | BG48: [1,] -0.009707127 -0.001546615 0.006336927 0.009274255 0.0046929314 9.820170e-05 0.000000e+00 | BV48: 0 | BW48: 20 | BX48: 1.328675 | BY48: 0.11934944 | BZ48: =IF(BV48=1,BY48,NA()) -> #N/A
A49: 24 | B49: 0 | C49: 14 | D49: 100.37418 | E49: 18679 | F49: 7867 | G49: 5640 | H49: 5172 | I49: 13.9 | J49: 1980.2 | K49: 10832 | L49: 38398 | M49: 12089 | N49: 4106 | O49: 4698.55 | P49: 113.2 | Q49: 1100 | R49: 300 | U49: 24 | V49: 0 | W49: 14 | X49: =(D49-D$23)/D$24 -> 1.3173817 | Y49: =(E49-E$23)/E$24 -> -0.20627592 | Z49: =(F49-F$23)/F$24 -> 0.29938117 | AA49: =(G49-G$23)/G$24 -> -0.25083645 | AB49: =(H49-H$23)/H$24 -> -0.22635986 | AC49: =(I49-I$23)/I$24 -> 0.30968431 | AD49: =(J49-J$23)/J$24 -> 1.1743381 | AE49: =(K49-K$23)/K$24 -> -0.37584349 | ... AL49: =(R49-R$23)/R$24 -> -0.23981219 | AO49: odległość | AP49: =VARP(PCA!$X$26:$X$405) -> 0.99736842 | AQ49: -0.14931069 | AR49: 0.025230277 | AS49: -0.24620532 | AT49: -0.12749857 | AU49: 0.20698687 | AV49: -0.087396931 | AW49: -0.18283135 | AX49: -0.19609437 | AY49: -0.17944283 | AZ49: -0.12762288 | BA49: -0.1850523 | BB49: -0.18497237 | BC49: -0.18905873 | BD49: -0.083587772 | BG49: [2,] 0.079195502 -0.426070482 -0.179916616 0.267140664 -0.0025704910 -6.399929e-05 -7.525504e-01 | BV49: 0 | BW49: 21 | BX49: 1.6039222 | BY49: -1.2454588 | BZ49: =IF(BV49=1,BY49,NA()) -> #N/A
...

Sheet road data
B1: Bezledy | C1: Biała Podlaska | D1: Białystok | E1: Bielsko - Biała | F1: Bydgoszcz | G1: Ciechanów | H1: Cieszyn | I1: Częstochowa | J1: Elbląg | K1: Gdańsk | L1: Gorzów Wielkopolski | M1: Hrebenne | N1: Jelenia Góra | O1: Kalisz | P1: Katowice | Q1: Kielce | R1: Konin | S1: Koszalin | T1: Kraków | U1: Kudowa-Słone | V1: Legnica | W1: Leszno | X1: Lublin | Y1: Łódź | Z1: Nowy Sącz | AA1: Olsztyn | AB1: Olszyna | AC1: Opole | AD1: Ostrołęka | AE1: Piotrków Trybunalski | AF1: Płock | AG1: Poznań | AH1: Przemyśl | AI1: Radom | AJ1: Rzeszów | AK1: Siedlce | AL1: Skierniewice | AM1: Słupsk | AN1: Suwałki | AO1: Szczecin | AP1: Świnoujście | AQ1: Tarnobrzeg | AR1: Tarnów | AS1: Terespol | AT1: Toruń | AU1: Warszawa | AV1: Włocławek | AW1: Wrocław | AX1: Zakopane | AY1: Zielona Góra
A2: =AY2 -> Bezledy | AY2: Bezledy
A3: =AY3 -> Biała Podlaska | B3: 382 | AY3: Biała Podlaska
A4: =AY4 -> Białystok | B4: 224 | C4: 154 | AY4: Białystok
A5: =AY5 -> Bielsko - Biała | B5: 622 | C5: 491 | D5: 542 | AY5: Bielsko - Biała
A6: =AY6 -> Bydgoszcz | B6: 288 | C6: 415 | D6: 400 | E6: 460 | AY6: Bydgoszcz
A7: =AY7 -> Ciechanów | B7: 208 | C7: 237 | D7: 190 | E7: 500 | F7: 205 | AY7: Ciechanów
A8: =AY8 -> Cieszyn | B8: 741 | C8: 496 | D8: 562 | E8: 35 | F8: 479 | G8: 472 | AY8: Cieszyn
A9: =AY9 -> Częstochowa | B9: 490 | C9: 383 | D9: 410 | E9: 130 | F9: 330 | G9: 320 | H9: 151 | AY9: Częstochowa
A10: =AY10 -> Elbląg | B10: 133 | C10: 428 | D10: 335 | E10: 595 | F10: 175 | G10: 220 | H10: 652 | I10: 500 | AY10: Elbląg
A11: =AY11 -> Gdańsk | B11: 192 | C11: 487 | D11: 395 | E11: 595 | F11: 170 | G11: 280 | H11: 670 | I11: 450 | J11: 60 | AY11: Gdańsk
A12: =AY12 -> Gorzów Wielkopolski | B12: 489 | C12: 600 | D12: 608 | E12: 495 | F12: 210 | G12: 425 | H12: 509 | I12: 435 | J12: 355 | K12: 315 | AY12: Gorzów Wielkopolski
A13: =AY13 -> Hrebenne | B13: 57 | C13: 245 | D13: 400 | E13: 392 | F13: 576 | G13: 412 | H13: 427 | I13: 401 | J13: 617 | K13: 660 | L13: 723 | AY13: Hrebenne
A14: =AY14 -> Jelenia Góra | B14: 647 | C14: 631 | D14: 630 | E14: 340 | F14: 375 | G14: 575 | H14: 277 | I14: 300 | J14: 520 | K14: 570 | L14: 255 | M14: 685 | AY14: Jelenia Góra
A15: =AY15 -> Kalisz | B15: 428 | C15: 416 | D15: 445 | E15: 300 | F15: 180 | G15: 265 | H15: 320 | I15: 195 | J15: 350 | K15: 300 | L15: 245 | M15: 479 | N15: 245 | AY15: Kalisz
A16: =AY16 -> Katowice | B16: 567 | C16: 460 | D16: 490 | E16: 55 | F16: 405 | G16: 400 | H16: 74 | I16: 75 | J16: 580 | K16: 530 | L16: 465 | M16: 433 | N16: 310 | O16: 270 | AY16: Katowice
A17: =AY17 -> Kielce | B17: 485 | C17: 268 | D17: 365 | E17: 225 | F17: 345 | G17: 275 | H17: 286 | I17: 135 | J17: 495 | K17: 505 | L17: 465 | M17: 266 | N17: 435 | O17: 220 | P17: 210 | AY17: Kielce
A18: =AY18 -> Konin | B18: 371 | C18: 364 | D18: 390 | E18: 340 | F18: 120 | G18: 205 | H18: 358 | I18: 209 | J18: 295 | K18: 245 | L18: 235 | M18: 486 | N18: 375 | O18: 55 | P18: 285 | Q18: 260 | AY18: Konin
A19: =AY19 -> Koszalin | B19: 395 | C19: 600 | D19: 585 | E19: 640 | F19: 185 | G19: 390 | H19: 664 | I19: 490 | J19: 260 | K19: 205 | L19: 225 | M19: 749 | N19: 485 | O19: 350 | P19: 590 | Q19: 530 | R19: 309 | AY19: Koszalin
A20: =AY20 -> Kraków | B20: 621 | C20: 374 | D20: 445 | E20: 85 | F20: 477 | G20: 415 | H20: 122 | I20: 150 | J20: 630 | K20: 610 | L20: 585 | M20: 306 | N20: 390 | O20: 340 | P20: 70 | Q20: 135 | R20: 355 | S20: 660 | AY20: Kraków
A21: =AY21 -> Kudowa-Słone | B21: 704 | C21: 621 | D21: 649 | E21: 256 | F21: 432 | G21: 559 | H21: 234 | I21: 238 | J21: 711 | K21: 645 | L21: 376 | M21: 595 | N21: 154 | O21: 260 | P21: 217 | Q21: 372 | R21: 317 | S21: 553 | T21: 289 | AY21: Kudowa-Słone
A22: =AY22 -> Legnica | B22: 580 | C22: 576 | D22: 610 | E22: 300 | F22: 375 | G22: 445 | H22: 313 | I22: 250 | J22: 455 | K22: 505 | L22: 215 | M22: 630 | N22: 65 | O22: 190 | P22: 270 | Q22: 370 | R22: 240 | S22: 420 | T22: 340 | U22: 159 | AY22: Legnica
A23: =AY23 -> Leszno | B23: 480 | C23: 505 | D23: 510 | E23: 325 | F23: 205 | G23: 345 | H23: 336 | I23: 275 | J23: 355 | K23: 405 | L23: 210 | M23: 604 | N23: 165 | O23: 125 | P23: 290 | Q23: 345 | R23: 140 | S23: 310 | T23: 369 | U23: 235 | V23: 100 | AY23: Leszno
A24: =AY24 -> Lublin | B24: 437 | C24: 121 | D24: 295 | E24: 340 | F24: 420 | G24: 280 | H24: 375 | I24: 290 | J24: 485 | K24: 515 | L24: 580 | M24: 144 | N24: 510 | O24: 335 | P24: 330 | Q24: 180 | R24: 369 | S24: 605 | T24: 255 | U24: 551 | V24: 485 | W24: 460 | AY24: Lublin
A25: =AY25 -> Łódź | B25: 364 | C25: 297 | D25: 215 | E25: 260 | F25: 205 | G25: 180 | H25: 277 | I25: 129 | J25: 375 | K25: 340 | L25: 345 | M25: 396 | N25: 355 | O25: 120 | P25: 205 | Q25: 135 | R25: 110 | S25: 450 | T25: 275 | U25: 344 | V25: 295 | W25: 245 | X25: 250 | AY25: Łódź
A26: =AY26 -> Nowy Sącz | B26: 662 | C26: 406 | D26: 510 | E26: 150 | F26: 520 | G26: 455 | H26: 187 | I26: 250 | J26: 675 | K26: 680 | L26: 650 | M26: 346 | N26: 490 | O26: 415 | P26: 175 | Q26: 175 | R26: 455 | S26: 765 | T26: 100 | U26: 390 | V26: 440 | W26: 465 | X26: 285 | Y26: 315 | AY26: Nowy Sącz
A27: =AY27 -> Olsztyn | B27: 89 | C27: 238 | D27: 235 | E27: 535 | F27: 200 | G27: 120 | H27: 522 | I27: 400 | J27: 100 | K27: 160 | L27: 410 | M27: 531 | N27: 560 | O27: 360 | P27: 480 | Q27: 395 | R27: 280 | S27: 310 | T27: 537 | U27: 615 | V27: 490 | W27: 390 | X27: 385 | Y27: 275 | Z27: 575 | AY27: Olsztyn
A28: =AY28 -> Olszyna | B28: 609 | C28: 662 | D28: 716 | E28: 458 | F28: 336 | G28: 497 | H28: 391 | I28: 457 | J28: 509 | K28: 487 | L28: 186 | M28: 729 | N28: 150 | O28: 282 | P28: 427 | Q28: 502 | R28: 298 | S28: 413 | T28: 466 | U28: 284 | V28: 125 | W28: 157 | X28: 585 | Y28: 395 | Z28: 567 | AA28: 535 | AY28: Olszyna
A29: =AY29 -> Opole | B29: 564 | C29: 477 | D29: 505 | E29: 145 | F29: 340 | G29: 415 | H29: 156 | I29: 95 | J29: 515 | K29: 515 | L29: 355 | M29: 515 | N29: 205 | O29: 165 | P29: 110 | Q29: 230 | R29: 220 | S29: 515 | T29: 185 | U29: 144 | V29: 155 | W29: 180 | X29: 405 | Y29: 200 | Z29: 285 | AA29: 475 | AB29: 282 | AY29: Opole
A30: =AY30 -> Ostrołęka | B30: 179 | C30: 203 | D30: 113 | E30: 514 | F30: 290 | G30: 84 | H30: 486 | I30: 335 | J30: 225 | K30: 284 | L30: 509 | M30: 402 | N30: 588 | O30: 346 | P30: 412 | Q30: 291 | R30: 294 | S30: 475 | T30: 427 | U30: 573 | V30: 533 | W30: 433 | X30: 258 | Y30: 253 | Z30: 468 | AA30: 125 | AB30: 581 | AC30: 429 | AY30: Ostrołęka
A31: =AY31 -> Piotrków Trybunalski | B31: 409 | C31: 297 | D31: 330 | E31: 215 | F31: 275 | G31: 240 | H31: 232 | I31: 80 | J31: 280 | K31: 410 | L31: 370 | M31: 351 | N31: 335 | O31: 130 | P31: 160 | Q31: 90 | R31: 155 | S31: 435 | T31: 237 | U31: 319 | V31: 280 | W31: 255 | X31: 205 | Y31: 45 | Z31: 270 | AA31: 310 | AB31: 378 | AC31: 175 | AD31: 254 | AY31: Piotrków Trybunalski
A32: =AY32 -> Płock | B32: 267 | C32: 274 | D32: 275 | E32: 355 | F32: 150 | G32: 85 | H32: 374 | I32: 229 | J32: 280 | K32: 285 | L32: 340 | M32: 424 | N32: 430 | O32: 185 | P32: 300 | Q32: 235 | R32: 129 | S32: 335 | T32: 380 | U32: 443 | V32: 375 | W32: 265 | X32: 280 | Y32: 95 | Z32: 440 | AA32: 180 | AB32: 413 | AC32: 315 | AD32: 168 | AE32: 140 | AY32: Płock
A33: =AY33 -> Poznań | B33: 403 | C33: 466 | D33: 485 | E33: 400 | F33: 130 | G33: 290 | H33: 413 | I33: 280 | J33: 305 | K33: 330 | L33: 135 | M33: 589 | N33: 245 | O33: 110 | P33: 360 | Q33: 330 | R33: 100 | S33: 240 | T33: 440 | U33: 317 | V33: 175 | W33: 75 | X33: 445 | Y33: 210 | Z33: 509 | AA33: 330 | AB33: 206 | AC33: 255 | AD33: 375 | AE33: 240 | AF33: 209 | AY33: Poznań
A34: =AY34 -> Przemyśl | B34: 642 | C34: 336 | D34: 470 | E34: 340 | F34: 590 | G34: 475 | H34: 374 | I34: 385 | J34: 695 | K34: 750 | L34: 710 | M34: 119 | N34: 610 | O34: 470 | P34: 325 | Q34: 250 | R34: 509 | S34: 770 | T34: 250 | U34: 580 | V34: 595 | W34: 615 | X34: 215 | Y34: 385 | Z34: 229 | AA34: 595 | AB34: 718 | AC34: 435 | AD34: 463 | AE34: 340 | AF34: 440 | AG34: 595 | AY34: Przemyśl
A35: =AY35 -> Radom | B35: 411 | C35: 94 | D35: 295 | E35: 295 | F35: 315 | G35: 205 | H35: 332 | I35: 185 | J35: 420 | K35: 450 | L35: 475 | M35: 248 | N35: 435 | O35: 230 | P35: 260 | Q35: 75 | R35: 269 | S35: 500 | T35: 210 | U35: 447 | V35: 380 | W35: 355 | X35: 105 | Y35: 150 | Z35: 250 | AA35: 310 | AB35: 481 | AC35: 305 | AD35: 217 | AE35: 105 | AF35: 170 | AG35: 340 | AH35: 270 | AY35: Radom
A36: =AY36 -> Rzeszów | B36: 609 | C36: 296 | D36: 430 | E36: 255 | F36: 525 | G36: 410 | H36: 290 | I36: 315 | J36: 625 | K36: 685 | L36: 645 | M36: 150 | N36: 560 | O36: 400 | P36: 240 | Q36: 180 | R36: 440 | S36: 705 | T36: 170 | U36: 496 | V36: 510 | W36: 525 | X36: 175 | Y36: 320 | Z36: 160 | AA36: 525 | AB36: 634 | AC36: 350 | AD36: 423 | AE36: 275 | AF36: 375 | AG36: 510 | AH36: 85 | AI36: 205 | AY36: Rzeszów
A37: =AY37 -> Siedlce | B37: 321 | C37: 61 | D37: 170 | E37: 480 | F37: 355 | G37: 175 | H37: 473 | I37: 320 | J37: 365 | K37: 425 | L37: 540 | M37: 260 | N37: 575 | O37: 355 | P37: 400 | Q37: 260 | R37: 309 | S37: 510 | T37: 395 | U37: 560 | V37: 520 | W37: 445 | X37: 115 | Y37: 235 | Z37: 409 | AA37: 265 | AB37: 601 | AC37: 415 | AD37: 142 | AE37: 240 | AF37: 215 | AG37: 405 | AH37: 330 | AI37: 185 | AJ37: 300 | AY37: Siedlce
A38: =AY38 -> Skierniewice | B38: 359 | C38: 242 | D38: 270 | E38: 300 | F38: 240 | G38: 175 | H38: 322 | I38: 170 | J38: 365 | K38: 365 | L38: 380 | M38: 362 | N38: 425 | O38: 180 | P38: 245 | Q38: 165 | R38: 145 | S38: 415 | T38: 320 | U38: 436 | V38: 370 | W38: 305 | X38: 220 | Y38: 60 | Z38: 369 | AA38: 270 | AB38: 457 | AC38: 265 | AD38: 194 | AE38: 90 | AF38: 90 | AG38: 245 | AH38: 385 | AI38: 115 | AJ38: 320 | AK38: 180 | AY38: Skierniewice
A39: =AY39 -> Słupsk | B39: 326 | C39: 587 | D39: 525 | E39: 660 | F39: 200 | G39: 360 | H39: 723 | I39: 570 | J39: 195 | K39: 135 | L39: 295 | M39: 727 | N39: 520 | O39: 380 | P39: 650 | Q39: 580 | R39: 320 | S39: 70 | T39: 720 | U39: 595 | V39: 455 | W39: 355 | X39: 595 | Y39: 405 | Z39: 770 | AA39: 295 | AB39: 482 | AC39: 535 | AD39: 410 | AE39: 490 | AF39: 355 | AG39: 280 | AH39: 810 | AI39: 530 | AJ39: 735 | AK39: 525 | AL39: 435 | AY39: Słupsk
A40: =AY40 -> Suwałki | B40: 186 | C40: 270 | D40: 116 | E40: 674 | F40: 408 | G40: 253 | H40: 646 | I40: 646 | J40: 309 | K40: 368 | L40: 616 | M40: 516 | N40: 748 | O40: 515 | P40: 572 | Q40: 451 | R40: 463 | S40: 519 | T40: 587 | U40: 736 | V40: 693 | W40: 579 | X40: 372 | Y40: 409 | Z40: 657 | AA40: 209 | AB40: 729 | AC40: 589 | AD40: 169 | AE40: 414 | AF40: 337 | AG40: 523 | AH40: 587 | AI40: 377 | AJ40: 547 | AK40: 282 | AL40: 354 | AM40: 502 | AY40: Suwałki
...

Sheet full road data
A1: dist | B1: Bezledy | C1: Biała Podlaska | D1: Białystok | E1: Bielsko - Biała | F1: Bydgoszcz | G1: Ciechanów | H1: Cieszyn | I1: Częstochowa | J1: Elbląg | K1: Gdańsk | L1: Gorzów Wielkopolski | M1: Hrebenne | N1: Jelenia Góra | O1: Kalisz | P1: Katowice | Q1: Kielce | R1: Konin | S1: Koszalin | T1: Kraków | U1: Kudowa-Słone | V1: Legnica | W1: Leszno | X1: Lublin | Y1: Łódź | Z1: Nowy Sącz | AA1: Olsztyn | AB1: Olszyna | AC1: Opole | AD1: Ostrołęka | AE1: Piotrków Trybunalski | AF1: Płock | AG1: Poznań | AH1: Przemyśl | AI1: Radom | AJ1: Rzeszów | AK1: Siedlce | AL1: Skierniewice | AM1: Słupsk | AN1: Suwałki | AO1: Szczecin | AP1: Świnoujście | AQ1: Tarnobrzeg | AR1: Tarnów | AS1: Terespol | AT1: Toruń | AU1: Warszawa | AV1: Włocławek | AW1: Wrocław | AX1: Zakopane | AY1: Zielona Góra
A2: Bezledy | B2: 0 | C2: 382 | D2: 224 | E2: 622 | F2: 288 | G2: 208 | H2: 741 | I2: 490 | J2: 133 | K2: 192 | L2: 489 | M2: 57 | N2: 647 | O2: 428 | P2: 567 | Q2: 485 | R2: 371 | S2: 395 | T2: 621 | U2: 704 | V2: 580 | W2: 480 | X2: 437 | Y2: 364 | Z2: 662 | AA2: 89 | AB2: 609 | AC2: 564 | AD2: 179 | AE2: 409 | AF2: 267 | AG2: 403 | AH2: 642 | AI2: 411 | AJ2: 609 | AK2: 321 | AL2: 359 | AM2: 326 | AN2: 186 | AO2: 539 | AP2: 546 | AQ2: 540 | AR2: 603 | AS2: 421 | AT2: 256 | AU2: 308 | AV2: 314 | AW2: 564 | AX2: 728 | AY2: 550
A3: Biała Podlaska | B3: 382 | C3: 0 | D3: 154 | E3: 491 | F3: 415 | G3: 237 | H3: 496 | I3: 383 | J3: 428 | K3: 487 | L3: 600 | M3: 245 | N3: 631 | O3: 416 | P3: 460 | Q3: 268 | R3: 364 | S3: 600 | T3: 374 | U3: 621 | V3: 576 | W3: 505 | X3: 121 | Y3: 297 | Z3: 406 | AA3: 238 | AB3: 662 | AC3: 477 | AD3: 203 | AE3: 297 | AF3: 274 | AG3: 466 | AH3: 336 | AI3: 94 | AJ3: 296 | AK3: 61 | AL3: 242 | AM3: 587 | AN3: 270 | AO3: 675 | AP3: 675 | AQ3: 225 | AR3: 347 | AS3: 39 | AT3: 369 | AU3: 162 | AV3: 322 | AW3: 504 | AX3: 481 | AY3: 588
A4: Białystok | B4: 224 | C4: 154 | D4: 0 | E4: 542 | F4: 400 | G4: 190 | H4: 562 | I4: 410 | J4: 335 | K4: 395 | L4: 608 | M4: 400 | N4: 630 | O4: 445 | P4: 490 | Q4: 365 | R4: 390 | S4: 585 | T4: 445 | U4: 649 | V4: 610 | W4: 510 | X4: 295 | Y4: 215 | Z4: 510 | AA4: 235 | AB4: 716 | AC4: 505 | AD4: 113 | AE4: 330 | AF4: 275 | AG4: 485 | AH4: 470 | AI4: 295 | AJ4: 430 | AK4: 170 | AL4: 270 | AM4: 525 | AN4: 116 | AO4: 660 | AP4: 710 | AQ4: 390 | AR4: 480 | AS4: 193 | AT4: 350 | AU4: 190 | AV4: 315 | AW4: 535 | AX4: 636 | AY4: 615
A5: Bielsko - Biała | B5: 622 | C5: 491 | D5: 542 | E5: 0 | F5: 460 | G5: 500 | H5: 35 | I5: 130 | J5: 595 | K5: 595 | L5: 495 | M5: 392 | N5: 340 | O5: 300 | P5: 55 | Q5: 225 | R5: 340 | S5: 640 | T5: 85 | U5: 256 | V5: 300 | W5: 325 | X5: 340 | Y5: 260 | Z5: 150 | AA5: 535 | AB5: 458 | AC5: 145 | AD5: 514 | AE5: 215 | AF5: 355 | AG5: 400 | AH5: 340 | AI5: 295 | AJ5: 255 | AK5: 480 | AL5: 300 | AM5: 660 | AN5: 674 | AO5: 600 | AP5: 728 | AQ5: 233 | AR5: 170 | AS5: 530 | AT5: 420 | AU5: 400 | AV5: 360 | AW5: 230 | AX5: 129 | AY5: 385
A6: Bydgoszcz | B6: 288 | C6: 415 | D6: 400 | E6: 460 | F6: 0 | G6: 205 | H6: 479 | I6: 330 | J6: 175 | K6: 170 | L6: 210 | M6: 576 | N6: 375 | O6: 180 | P6: 405 | Q6: 345 | R6: 120 | S6: 185 | T6: 477 | U6: 432 | V6: 375 | W6: 205 | X6: 420 | Y6: 205 | Z6: 520 | AA6: 200 | AB6: 336 | AC6: 340 | AD6: 290 | AE6: 275 | AF6: 150 | AG6: 130 | AH6: 590 | AI6: 315 | AJ6: 525 | AK6: 355 | AL6: 240 | AM6: 200 | AN6: 408 | AO6: 260 | AP6: 312 | AQ6: 449 | AR6: 460 | AS6: 454 | AT6: 45 | AU6: 255 | AV6: 105 | AW6: 275 | AX6: 584 | AY6: 260
A7: Ciechanów | B7: 208 | C7: 237 | D7: 190 | E7: 500 | F7: 205 | G7: 0 | H7: 472 | I7: 320 | J7: 220 | K7: 280 | L7: 425 | M7: 412 | N7: 575 | O7: 265 | P7: 400 | Q7: 275 | R7: 205 | S7: 390 | T7: 415 | U7: 559 | V7: 445 | W7: 345 | X7: 280 | Y7: 180 | Z7: 455 | AA7: 120 | AB7: 497 | AC7: 415 | AD7: 84 | AE7: 240 | AF7: 85 | AG7: 290 | AH7: 475 | AI7: 205 | AJ7: 410 | AK7: 175 | AL7: 175 | AM7: 360 | AN7: 253 | AO7: 465 | AP7: 518 | AQ7: 332 | AR7: 395 | AS7: 276 | AT7: 160 | AU7: 100 | AV7: 130 | AW7: 445 | AX7: 520 | AY7: 425
A8: Cieszyn | B8: 741 | C8: 496 | D8: 562 | E8: 35 | F8: 479 | G8: 472 | H8: 0 | I8: 151 | J8: 652 | K8: 670 | L8: 509 | M8: 427 | N8: 277 | O8: 320 | P8: 74 | Q8: 286 | R8: 358 | S8: 664 | T8: 122 | U8: 234 | V8: 313 | W8: 336 | X8: 375 | Y8: 277 | Z8: 187 | AA8: 522 | AB8: 391 | AC8: 156 | AD8: 486 | AE8: 232 | AF8: 374 | AG8: 413 | AH8: 374 | AI8: 332 | AJ8: 290 | AK8: 473 | AL8: 322 | AM8: 723 | AN8: 646 | AO8: 613 | AP8: 696 | AQ8: 268 | AR8: 205 | AS8: 535 | AT8: 437 | AU8: 372 | AV8: 379 | AW8: 241 | AX8: 164 | AY8: 397
A9: Częstochowa | B9: 490 | C9: 383 | D9: 410 | E9: 130 | F9: 330 | G9: 320 | H9: 151 | I9: 0 | J9: 500 | K9: 450 | L9: 435 | M9: 401 | N9: 300 | O9: 195 | P9: 75 | Q9: 135 | R9: 209 | S9: 490 | T9: 150 | U9: 238 | V9: 250 | W9: 275 | X9: 290 | Y9: 129 | Z9: 250 | AA9: 400 | AB9: 457 | AC9: 95 | AD9: 335 | AE9: 80 | AF9: 229 | AG9: 280 | AH9: 385 | AI9: 185 | AJ9: 315 | AK9: 320 | AL9: 170 | AM9: 570 | AN9: 646 | AO9: 550 | AP9: 631 | AQ9: 241 | AR9: 237 | AS9: 422 | AT9: 320 | AU9: 220 | AV9: 380 | AW9: 180 | AX9: 239 | AY9: 335
A10: Elbląg | B10: 133 | C10: 428 | D10: 335 | E10: 595 | F10: 175 | G10: 220 | H10: 652 | I10: 500 | J10: 0 | K10: 60 | L10: 355 | M10: 617 | N10: 520 | O10: 350 | P10: 580 | Q10: 495 | R10: 295 | S10: 260 | T10: 630 | U10: 711 | V10: 455 | W10: 355 | X10: 485 | Y10: 375 | Z10: 675 | AA10: 100 | AB10: 509 | AC10: 515 | AD10: 225 | AE10: 280 | AF10: 280 | AG10: 305 | AH10: 695 | AI10: 420 | AJ10: 625 | AK10: 365 | AL10: 365 | AM10: 195 | AN10: 309 | AO10: 405 | AP10: 441 | AQ10: 551 | AR10: 615 | AS10: 467 | AT10: 180 | AU10: 320 | AV10: 235 | AW10: 470 | AX10: 739 | AY10: 435
A11: Gdańsk | B11: 192 | C11: 487 | D11: 395 | E11: 595 | F11: 170 | G11: 280 | H11: 670 | I11: 450 | J11: 60 | K11: 0 | L11: 315 | M11: 660 | N11: 570 | O11: 300 | P11: 530 | Q11: 505 | R11: 245 | S11: 205 | T11: 610 | U11: 645 | V11: 505 | W11: 405 | X11: 515 | Y11: 340 | Z11: 680 | AA11: 160 | AB11: 487 | AC11: 515 | AD11: 284 | AE11: 410 | AF11: 285 | AG11: 330 | AH11: 750 | AI11: 450 | AJ11: 685 | AK11: 425 | AL11: 365 | AM11: 135 | AN11: 368 | AO11: 365 | AP11: 354 | AQ11: 610 | AR11: 620 | AS11: 526 | AT11: 180 | AU11: 341 | AV11: 235 | AW11: 485 | AX11: 691 | AY11: 425
A12: Gorzów Wielkopolski | B12: 489 | C12: 600 | D12: 608 | E12: 495 | F12: 210 | G12: 425 | H12: 509 | I12: 435 | J12: 355 | K12: 315 | L12: 0 | M12: 723 | N12: 255 | O12: 245 | P12: 465 | Q12: 465 | R12: 235 | S12: 225 | T12: 585 | U12: 376 | V12: 215 | W12: 210 | X12: 580 | Y12: 345 | Z12: 650 | AA12: 410 | AB12: 186 | AC12: 355 | AD12: 509 | AE12: 370 | AF12: 340 | AG12: 135 | AH12: 710 | AI12: 475 | AJ12: 645 | AK12: 540 | AL12: 380 | AM12: 295 | AN12: 616 | AO12: 105 | AP12: 200 | AQ12: 570 | AR12: 580 | AS12: 639 | AT12: 255 | AU12: 440 | AV12: 295 | AW12: 270 | AX12: 625 | AY12: 110
A13: Hrebenne | B13: 57 | C13: 245 | D13: 400 | E13: 392 | F13: 576 | G13: 412 | H13: 427 | I13: 401 | J13: 617 | K13: 660 | L13: 723 | M13: 0 | N13: 685 | O13: 479 | P13: 433 | Q13: 266 | R13: 486 | S13: 749 | T13: 306 | U13: 595 | V13: 630 | W13: 604 | X13: 144 | Y13: 396 | Z13: 346 | AA13: 531 | AB13: 729 | AC13: 515 | AD13: 402 | AE13: 351 | AF13: 424 | AG13: 589 | AH13: 119 | AI13: 248 | AJ13: 150 | AK13: 260 | AL13: 362 | AM13: 727 | AN13: 516 | AO13: 825 | AP13: 877 | AQ13: 160 | AR13: 235 | AS13: 284 | AT13: 530 | AU13: 312 | AV13: 472 | AW13: 558 | AX13: 443 | AY13: 687
... A51: Zielona Góra | B51: 550 | C51: 588 | D51: 615 | E51: 385 | F51: 260 | G51: 425 | H51: 397 | I51: 335 | J51: 435 | K51: 425 | L51: 110 | M51: 687 | N51: 145 | O51: 210 | P51: 355 | Q51: 430 | R51: 229 | S51: 340 | T51: 475 | U51: 264 | V51: 105 | W51: 85 | X51: 545 | Y51: 325 | Z51: 529 | AA51: 460 | AB51: 74 | AC51: 240 | AD51: 507 | AE51: 335 | AF51: 340 | AG51: 130 | AH51: 675 | AI51: 440 | AJ51: 640 | AK51: 525 | AL51: 385 | AM51: 410 | AN51: 655 | AO51: 215 | AP51: 312 | AQ51: 534 | AR51: 508 | AS51: 627 | AT51: 279 | AU51: 425 | AV51: 290 | AW51: 155 | AX51: 498 | AY51: 0
